Wed Feb 16 02:59:21 CET 2022 : Servidor de red Apache Derby: Se ha iniciado 10.14.2.0 - (1828579) y está listo para aceptar las conexiones en el puerto 1527
----------------------------------------------------------------
Wed Feb 16 02:59:25 CET 2022:
 Iniciando instancia a816c00e-017f-0041-6a2f-000010595d1b de Derby, versión The Apache Software Foundation - Apache Derby - 10.14.2.0 - (1828579): 
en el directorio de base de datos C:\Users\David\Documents\2-DAM\PMDM\Práctica06\Proyecto6\database\practica6 con el cargador de clases jdk.internal.loader.ClassLoaders$AppClassLoader@73d16e93
Cargado desde file:/C:/Users/David/GlassFish/javadb/lib/derby.jar
java.vendor=Oracle Corporation
java.runtime.version=16.0.1+9-24
user.dir=C:\Users\David\GlassFish\javadb
os.name=Windows 10
os.arch=amd64
os.version=10.0
derby.system.home=C:\Users\David\Documents\2-DAM\PMDM\Práctica06\Proyecto6\database
Cargador de clases de base de datos iniciado - derby.database.classpath=''
Wed Feb 16 02:59:25 CET 2022 Thread[DRDAConnThread_2,5,main] (XID = 2859), (SESSIONID = 0), (DATABASE = practica6), (DRDAID = {1}), Cleanup action starting
java.sql.SQLNonTransientConnectionException: Se ha producido un fallo de autenticación de conexión. Motivo: Autenticación no válida..
	at org.apache.derby.impl.jdbc.SQLExceptionFactory.getSQLException(Unknown Source)
	at org.apache.derby.impl.jdbc.SQLExceptionFactory.getSQLException(Unknown Source)
	at org.apache.derby.impl.jdbc.Util.generateCsSQLException(Unknown Source)
	at org.apache.derby.impl.jdbc.Util.generateCsSQLException(Unknown Source)
	at org.apache.derby.impl.jdbc.EmbedConnection.newSQLException(Unknown Source)
	at org.apache.derby.impl.jdbc.EmbedConnection.checkUserCredentials(Unknown Source)
	at org.apache.derby.impl.jdbc.EmbedConnection.<init>(Unknown Source)
	at org.apache.derby.jdbc.InternalDriver$1.run(Unknown Source)
	at org.apache.derby.jdbc.InternalDriver$1.run(Unknown Source)
	at java.base/java.security.AccessController.doPrivileged(AccessController.java:554)
	at org.apache.derby.jdbc.InternalDriver.getNewEmbedConnection(Unknown Source)
	at org.apache.derby.jdbc.InternalDriver.connect(Unknown Source)
	at org.apache.derby.jdbc.InternalDriver.connect(Unknown Source)
	at org.apache.derby.jdbc.EmbeddedDriver.connect(Unknown Source)
	at org.apache.derby.impl.drda.Database.makeConnection(Unknown Source)
	at org.apache.derby.impl.drda.DRDAConnThread.getConnFromDatabaseName(Unknown Source)
	at org.apache.derby.impl.drda.DRDAConnThread.verifyUserIdPassword(Unknown Source)
	at org.apache.derby.impl.drda.DRDAConnThread.parseSECCHK(Unknown Source)
	at org.apache.derby.impl.drda.DRDAConnThread.parseDRDAConnection(Unknown Source)
	at org.apache.derby.impl.drda.DRDAConnThread.processCommands(Unknown Source)
	at org.apache.derby.impl.drda.DRDAConnThread.run(Unknown Source)
Caused by: ERROR 08004: Se ha producido un fallo de autenticación de conexión. Motivo: Autenticación no válida..
	at org.apache.derby.iapi.error.StandardException.newException(Unknown Source)
	at org.apache.derby.impl.jdbc.SQLExceptionFactory.wrapArgsForTransportAcrossDRDA(Unknown Source)
	... 21 more
============= begin nested exception, level (1) ===========
ERROR 08004: Se ha producido un fallo de autenticación de conexión. Motivo: Autenticación no válida..
	at org.apache.derby.iapi.error.StandardException.newException(Unknown Source)
	at org.apache.derby.impl.jdbc.SQLExceptionFactory.wrapArgsForTransportAcrossDRDA(Unknown Source)
	at org.apache.derby.impl.jdbc.SQLExceptionFactory.getSQLException(Unknown Source)
	at org.apache.derby.impl.jdbc.SQLExceptionFactory.getSQLException(Unknown Source)
	at org.apache.derby.impl.jdbc.Util.generateCsSQLException(Unknown Source)
	at org.apache.derby.impl.jdbc.Util.generateCsSQLException(Unknown Source)
	at org.apache.derby.impl.jdbc.EmbedConnection.newSQLException(Unknown Source)
	at org.apache.derby.impl.jdbc.EmbedConnection.checkUserCredentials(Unknown Source)
	at org.apache.derby.impl.jdbc.EmbedConnection.<init>(Unknown Source)
	at org.apache.derby.jdbc.InternalDriver$1.run(Unknown Source)
	at org.apache.derby.jdbc.InternalDriver$1.run(Unknown Source)
	at java.base/java.security.AccessController.doPrivileged(AccessController.java:554)
	at org.apache.derby.jdbc.InternalDriver.getNewEmbedConnection(Unknown Source)
	at org.apache.derby.jdbc.InternalDriver.connect(Unknown Source)
	at org.apache.derby.jdbc.InternalDriver.connect(Unknown Source)
	at org.apache.derby.jdbc.EmbeddedDriver.connect(Unknown Source)
	at org.apache.derby.impl.drda.Database.makeConnection(Unknown Source)
	at org.apache.derby.impl.drda.DRDAConnThread.getConnFromDatabaseName(Unknown Source)
	at org.apache.derby.impl.drda.DRDAConnThread.verifyUserIdPassword(Unknown Source)
	at org.apache.derby.impl.drda.DRDAConnThread.parseSECCHK(Unknown Source)
	at org.apache.derby.impl.drda.DRDAConnThread.parseDRDAConnection(Unknown Source)
	at org.apache.derby.impl.drda.DRDAConnThread.processCommands(Unknown Source)
	at org.apache.derby.impl.drda.DRDAConnThread.run(Unknown Source)
============= end nested exception, level (1) ===========
Cleanup action completed
Wed Feb 16 02:59:25 CET 2022 Thread[DRDAConnThread_2,5,main] (DATABASE = practica6), (DRDAID = {1}), Se ha producido un fallo de autenticación de conexión. Motivo: Autenticación no válida..
----------------------------------------------------------------
Wed Feb 16 07:10:15 CET 2022: cerrando motor de Derby
----------------------------------------------------------------
Wed Feb 16 07:10:15 CET 2022:
Cerrando la instancia a816c00e-017f-0041-6a2f-000010595d1b en el directorio de base de datos C:\Users\David\Documents\2-DAM\PMDM\Práctica06\Proyecto6\database\practica6 con cargador de clases jdk.internal.loader.ClassLoaders$AppClassLoader@73d16e93
----------------------------------------------------------------
